<?xml version="1.0" ?>

<sdf version='1.6'>
  <model name='tern'>
  <pose>0 0 0.2 0 0 0</pose>

    <link name='base_link'>
      <pose>0 0 0.14 0 -0 0</pose>
      <frame name='base_link'>
      <pose>0 0 0.0 0 -0 0</pose>
      </frame>
      <inertial>
        <pose>0 0 0 0 -0 0</pose>
        <mass>0.5</mass>
        <inertia>
          <ixx>0.019804667</ixx>
          <ixy>0</ixy>
          <ixz>0</ixz>
          <iyy>0.00420416</iyy>
          <iyz>0</iyz>
          <izz>0.017475</izz>
        </inertia>
      </inertial>
      <collision name='base_link_collision'>
        <pose>0 0 0 0 -0 0</pose>
        <geometry>
          <box>
            <size>0.15 0.63 0.28</size>
          </box>
        </geometry>
        <surface>
          <contact>
            <ode>
              <max_vel>10</max_vel>
              <min_depth>0.01</min_depth>
            </ode>
          </contact>
          <friction>
            <ode/>
          </friction>
        </surface>
      </collision>
      <visual name='base_link_visual'>
        <pose>-0.116 0.345 -0.128 0 -1.57 1.57</pose>
        <geometry>
          <mesh>
            <scale>0.001 0.001 0.001</scale>
            <uri>model://tern/meshes/frame.dae</uri>
          </mesh>
        </geometry>
        <material>
          <script>
            <name>Gazebo/White</name>
            <uri>__default__</uri>
          </script>
        </material>
      </visual>
      <visual name='m0'>
        <pose>0.0 -0.205 0.13 0 -0 0</pose>
        <geometry>
          <cylinder>
            <length>0.03</length>
            <radius>0.02</radius>
          </cylinder>
        </geometry>
        <material>
          <script>
            <name>Gazebo/White</name>
            <uri>__default__</uri>
          </script>
        </material>
      </visual>
      <visual name='m1'>
        <pose>0.0 0.205 0.13 0 -0 0</pose>
        <geometry>
          <cylinder>
            <length>0.03</length>
            <radius>0.02</radius>
          </cylinder>
        </geometry>
        <material>
          <script>
            <name>Gazebo/White</name>
            <uri>__default__</uri>
          </script>
        </material>
      </visual>
      <gravity>1</gravity>
      <velocity_decay/>
      <self_collide>0</self_collide>
    </link>
    <link name='tern/imu_link'>
      <pose>0 0 0.14 0 0 0</pose>
      <inertial>
        <pose>0 0 0 0 0 0</pose>
        <mass>0.015</mass>
        <inertia>
          <ixx>1e-05</ixx>
          <ixy>0</ixy>
          <ixz>0</ixz>
          <iyy>1e-05</iyy>
          <iyz>0</iyz>
          <izz>1e-05</izz>
        </inertia>
      </inertial>
    </link>
    <!-- <joint name='tern/imu_joint' type='fixed'>
      <parent>base_link</parent>
      <child>tern/imu_link</child>
    </joint> -->
    <link name='rotor_left'>
      <pose>0.0 -0.205 0.293 0 -0 0</pose>
      <inertial>
        <pose>0 0 0 0 -0 0</pose>
        <mass>0.01</mass>
        <inertia>
          <ixx>3.541e-07</ixx>
          <ixy>0</ixy>
          <ixz>0</ixz>
          <iyy>3.335e-5</iyy>
          <iyz>0</iyz>
          <izz>3.336e-5</izz>
        </inertia>
      </inertial>
      <collision name='rotor_left_collision'>
        <pose>0 0 0 0 -0 0</pose>
        <geometry>
          <!-- <cylinder>
            <length>0.005</length>
            <radius>0.1</radius>
          </cylinder> -->
          <box>
            <size>0.20 0.02 0.005</size>
          </box>
        </geometry>
        <surface>
          <contact>
            <ode/>
          </contact>
          <friction>
            <ode/>
          </friction>
        </surface>
      </collision>
      <visual name='rotor_left_visual'>
        <pose>0.0006 0 0 0 0 0</pose>
        <geometry>
          <mesh>
            <scale>1 1 1</scale>
            <uri>model://tern/meshes/iris_prop_cw.dae</uri>
          </mesh>
        </geometry>
        <material>
          <script>
            <name>Gazebo/Black</name>
            <uri>__default__</uri>
          </script>
        </material>
      </visual>
      <gravity>1</gravity>
      <velocity_decay/>
      <self_collide>0</self_collide>
    </link>
    <joint name='rotor_left_joint' type='revolute'>
      <parent>base_link</parent>
      <child>rotor_left</child>
      <axis>
        <xyz>0 0 1</xyz>
        <limit>
          <lower>-1e+16</lower>
          <upper>1e+16</upper>
        </limit>
        <dynamics>
          <spring_reference>0</spring_reference>
          <spring_stiffness>0</spring_stiffness>
        </dynamics>
        <use_parent_model_frame>1</use_parent_model_frame>
      </axis>
    </joint>
    <link name='rotor_right'>
      <pose>0.0 0.205 0.293 0 0 0</pose>
      <inertial>
        <pose>0 0 0 0 -0 0</pose>
        <mass>0.01</mass>
        <inertia>
          <ixx>3.541e-07</ixx>
          <ixy>0</ixy>
          <ixz>0</ixz>
          <iyy>3.335e-5</iyy>
          <iyz>0</iyz>
          <izz>3.336e-5</izz>
        </inertia>
      </inertial>
      <collision name='rotor_right_collision'>
        <pose>0 0 0 0 0 0</pose>
        <geometry>
          <!-- <cylinder>
            <length>0.005</length>
            <radius>0.1</radius>
          </cylinder> -->
          <box>
            <size>0.20 0.02 0.005</size>
          </box>
        </geometry>
        <surface>
          <contact>
            <ode/>
          </contact>
          <friction>
            <ode/>
          </friction>
        </surface>
      </collision>
      <visual name='rotor_right_visual'>
        <pose>0.0045 0 0 0 0 0</pose>
        <geometry>
          <mesh>
            <scale>1 1 1</scale>
            <uri>model://tern/meshes/iris_prop_ccw.dae</uri>
          </mesh>
        </geometry>
        <material>
          <script>
            <name>Gazebo/WhiteGlow</name>
            <uri>__default__</uri>
          </script>
        </material>
      </visual>
      <gravity>1</gravity>
      <velocity_decay/>
      <self_collide>0</self_collide>
    </link>
    <joint name='rotor_right_joint' type='revolute'>
      <child>rotor_right</child>
      <parent>base_link</parent>
      <axis>
        <xyz>0 0 1</xyz>
        <limit>
          <lower>-1e+16</lower>
          <upper>1e+16</upper>
        </limit>
        <dynamics>
          <spring_reference>0</spring_reference>
          <spring_stiffness>0</spring_stiffness>
        </dynamics>
        <use_parent_model_frame>1</use_parent_model_frame>
      </axis>
    </joint>

    <link name="left_elevon">
      <pose>0.0 -0.2 0.132720 0 0 0</pose>
      <inertial>
        <mass>0.02</mass>
        <inertia>
          <ixx>7.719e-5</ixx>
          <ixy>0.0</ixy>
          <iyy>1.118e-5</iyy>
          <ixz>0.0</ixz>
          <iyz>0.0</iyz>
          <izz>6.645e-5</izz>
        </inertia>
        <pose>0 -0 -0.0 0 0 0</pose>
      </inertial>
      <visual name="left_elevon_visual">
		    <pose>0.0055 -0.33 0.134 0 1.57 1.57</pose>
		    <geometry>
          <mesh>
            <scale>0.001 0.001 0.001</scale>
            <uri>model://tern/meshes/elevon_2.dae</uri>
          </mesh>
        </geometry>
        <material>
          <script>
            <name>Gazebo/Grey</name>
            <uri>__default__</uri>
          </script>
        </material>
      </visual>
    </link>
    <link name="right_elevon">
      <pose>0.0 0.2 0.132720 0 0 0</pose>
      <inertial>
        <mass>0.02</mass>
        <inertia>
          <ixx>7.719e-5</ixx>
          <ixy>0.0</ixy>
          <iyy>1.118e-5</iyy>
          <ixz>0.0</ixz>
          <iyz>0.0</iyz>
          <izz>6.645e-5</izz>
        </inertia>
        <pose>0 0 -0.0 0 0 0</pose>
      </inertial>
     <visual name="right_elevon_visual">
		    <pose>0.0055 -0.33 0.134 0 1.57 1.57</pose>
        <geometry>
          <mesh>
            <scale>0.001 0.001 0.001</scale>
            <uri>model://tern/meshes/elevon_2.dae</uri>
          </mesh>
        </geometry>
        <material>
          <script>
            <name>Gazebo/Grey</name>
            <uri>__default__</uri>
          </script>
        </material>
     </visual>
    </link>

    <joint name='left_elevon_joint' type='revolute'>
      <parent>base_link</parent>
      <child>left_elevon</child>
      <pose>0 0.09 0.0 0 0 3.14</pose>
      <axis>
        <xyz>0 1 0</xyz>
        <limit>
          <lower>-1.57</lower>
          <upper>1.57</upper>
        </limit>
        <dynamics>
          <damping>1.000</damping>
        </dynamics>
      </axis>
      <physics>
        <ode>
          <implicit_spring_damper>1</implicit_spring_damper>
        </ode>
      </physics>
    </joint>
    <joint name='right_elevon_joint' type='revolute'>
      <parent>base_link</parent>
      <child>right_elevon</child>
      <pose>0 -0.09 0.0 0 0 0</pose>
      <axis>
        <xyz>0 1 0</xyz>
        <limit>
          <lower>-1.57</lower>
          <upper>1.57</upper>
        </limit>
        <dynamics>
          <damping>1.000</damping>
        </dynamics>
      </axis>
      <physics>
        <ode>
          <implicit_spring_damper>1</implicit_spring_damper>
        </ode>
      </physics>
    </joint>

    <plugin name="tern_control" filename="libtern_control.so">
        <force>50</force>
    </plugin>

    <!-- <joint name='elevator_joint' type='revolute'>
      <parent>base_link</parent>
      <child>elevator</child>
      <pose>0 0 -0.5 0.00 0 0.0</pose>
      <axis>
        <xyz>0 1 0</xyz>
        <limit>
          <lower>-0.53</lower>
          <upper>0.53</upper>
        </limit>
        <dynamics>
          <damping>1.000</damping>
        </dynamics>
      </axis>
      <physics>
        <ode>
          <implicit_spring_damper>1</implicit_spring_damper>
        </ode>
      </physics>
    </joint>
    <joint name='rudder_joint' type='revolute'>
      <parent>base_link</parent>
      <child>rudder</child>
      <pose>0 0 -0.5 0.00 0 0.0</pose>
      <axis>
        <xyz>1 0 0</xyz>
        <limit>
          <lower>-0.01</lower>
          <upper>0.01</upper>
        </limit>
        <dynamics>
          <damping>1.000</damping>
        </dynamics>
      </axis>
      <physics>
        <ode>
          <implicit_spring_damper>1</implicit_spring_damper>
        </ode>
      </physics>
    </joint> -->



    <!-- <plugin name="left_wing" filename="libgazebo_ts_aerodynamic_plugin.so">
      <k_lift>0.00000348</k_lift>
      <k_drag>0.00000175</k_drag>
      <k_pitch>-0.000000344</k_pitch>
      <cp>0 0.195 0.036</cp>
      <forward>0 0 1</forward>
      <upward>1 0 0</upward>
      <link_name>base_link</link_name>
      <motor_joint_name>rotor_left_joint</motor_joint_name>
      <control_joint_name>
        left_elevon_joint
      </control_joint_name>
    </plugin>

    <plugin name="right_wing" filename="libgazebo_ts_aerodynamic_plugin.so">
      <k_lift>0.00000348</k_lift>
      <k_drag>0.00000175</k_drag>
      <k_pitch>-0.000000344</k_pitch>
      <cp>0 -0.195 0.036</cp>
      <forward>0 0 1</forward>
      <upward>1 0 0</upward>
      <link_name>base_link</link_name>
      <motor_joint_name>rotor_right_joint</motor_joint_name>
      <control_joint_name>
        right_elevon_joint
      </control_joint_name>
    </plugin> -->
<!--
    <plugin name="left_wing" filename="libLiftDragPlugin.so">
      <a0>0.05984281113</a0>
      <cla>4.752798721</cla>
      <cda>0.6417112299</cda>
      <cma>-1.8</cma>
      <alpha_stall>0.6391428111</alpha_stall>
      <cla_stall>-3.85</cla_stall>
      <cda_stall>-0.9233984055</cda_stall>
      <cma_stall>0</cma_stall>
      <cp>0 0.3 0.0</cp>
      <area>0.15</area>
      <air_density>1.2041</air_density>
      <forward>0 0 1</forward>
      <upward>1 0 0</upward>
      <link_name>base_link</link_name>
      <control_joint_name>
        left_elevon_joint
      </control_joint_name>
      <control_joint_rad_to_cl>-0.5</control_joint_rad_to_cl>
    </plugin>
    <plugin name="right_wing" filename="libLiftDragPlugin.so">
      <a0>0.05984281113</a0>
      <cla>4.752798721</cla>
      <cda>0.6417112299</cda>
      <cma>-1.8</cma>
      <alpha_stall>0.6391428111</alpha_stall>
      <cla_stall>-3.85</cla_stall>
      <cda_stall>-0.9233984055</cda_stall>
      <cma_stall>0</cma_stall>
      <cp>0 -0.3 -0.0</cp>
      <area>0.15</area>
      <air_density>1.2041</air_density>
      <forward>0 0 1</forward>
      <upward>1 0 0</upward>
      <link_name>base_link</link_name>
      <control_joint_name>
        right_elevon_joint
      </control_joint_name>
      <control_joint_rad_to_cl>-0.5</control_joint_rad_to_cl>
    </plugin> -->

    <!-- <plugin name="elevator" filename="libLiftDragPlugin.so">
      <a0>0.05984281113</a0>
      <cla>4.752798721</cla>
      <cda>0.6417112299</cda>
      <cma>-1.8</cma>
      <alpha_stall>0.7391428111</alpha_stall>
      <cla_stall>-3.85</cla_stall>
      <cda_stall>-0.9233984055</cda_stall>
      <cma_stall>0</cma_stall>
      <cp>0 0 -0.5</cp>
      <area>0.005</area>
      <air_density>1.2041</air_density>
      <forward>0 0 1</forward>
      <upward>-1 0 0</upward>
      <link_name>base_link</link_name>
      <control_joint_name>
        elevator_joint
      </control_joint_name>
    </plugin>
    <plugin name="rudder" filename="libLiftDragPlugin.so">
      <a0>0.0</a0>
      <cla>4.752798721</cla>
      <cda>0.6417112299</cda>
      <cma>-1.8</cma>
      <alpha_stall>0.3391428111</alpha_stall>
      <cla_stall>-3.85</cla_stall>
      <cda_stall>-0.9233984055</cda_stall>
      <cma_stall>0</cma_stall>
      <cp>-0.1 0 -0.5</cp>
      <area>0.05</area>
      <air_density>1.2041</air_density>
      <forward>0 0 1</forward>
      <upward>0 1 0</upward>
      <link_name>base_link</link_name>
    </plugin> -->
    <!-- <plugin name='rosbag' filename='librotors_gazebo_multirotor_base_plugin.so'>
      <robotNamespace></robotNamespace>
      <linkName>base_link</linkName>
      <rotorVelocitySlowdownSim>10</rotorVelocitySlowdownSim>
    </plugin> -->
    <!-- <plugin name='front_left_motor_model' filename='librotors_gazebo_motor_model.so'> -->
    <!-- <plugin name='left_motor_model' filename='libgazebo_motor_model.so'>
      <robotNamespace></robotNamespace>
      <jointName>rotor_left_joint</jointName>
      <linkName>rotor_left</linkName>
      <turningDirection>cw</turningDirection>
      <timeConstantUp>0.016</timeConstantUp>
      <timeConstantDown>0.020</timeConstantDown>
      <maxRotVelocity>800</maxRotVelocity>
      <motorConstant>7.864e-06</motorConstant>
      <momentConstant>0.023</momentConstant>
      <commandSubTopic>/gazebo/command/motor_speed</commandSubTopic>
      <motorNumber>1</motorNumber>
      <rotorDragCoefficient>0</rotorDragCoefficient>
      <rollingMomentCoefficient>0</rollingMomentCoefficient>
      <motorSpeedPubTopic>/motor_speed/0</motorSpeedPubTopic>
      <rotorVelocitySlowdownSim>20</rotorVelocitySlowdownSim>
    </plugin> -->
    <!-- <plugin name='front_right_motor_model' filename='librotors_gazebo_motor_model.so'> -->
    <!-- <plugin name='right_motor_model' filename='libgazebo_motor_model.so'>
      <robotNamespace></robotNamespace>
      <jointName>rotor_right_joint</jointName>
      <linkName>rotor_right</linkName>
      <turningDirection>ccw</turningDirection>
      <timeConstantUp>0.016</timeConstantUp>
      <timeConstantDown>0.020</timeConstantDown>
      <maxRotVelocity>800</maxRotVelocity>
      <motorConstant>7.864e-06</motorConstant>
      <momentConstant>0.023</momentConstant>
      <commandSubTopic>/gazebo/command/motor_speed</commandSubTopic>
      <motorNumber>0</motorNumber>
      <rotorDragCoefficient>0</rotorDragCoefficient>
      <rollingMomentCoefficient>0</rollingMomentCoefficient>
      <motorSpeedPubTopic>/motor_speed/1</motorSpeedPubTopic>
      <rotorVelocitySlowdownSim>20</rotorVelocitySlowdownSim>
    </plugin> -->
    <!-- <plugin name='rotors_gazebo_imu_plugin' filename='librotors_gazebo_imu_plugin.so'> -->
    <!-- <plugin name='rotors_gazebo_imu_plugin' filename='libgazebo_imu_plugin.so'>
      <robotNamespace></robotNamespace>
      <linkName>tern/imu_link</linkName>
      <imuTopic>/imu</imuTopic>
      <gyroscopeNoiseDensity>0.0003394</gyroscopeNoiseDensity>
      <gyroscopeRandomWalk>3.8785e-05</gyroscopeRandomWalk>
      <gyroscopeBiasCorrelationTime>1000.0</gyroscopeBiasCorrelationTime>
      <gyroscopeTurnOnBiasSigma>0.0087</gyroscopeTurnOnBiasSigma>
      <accelerometerNoiseDensity>0.004</accelerometerNoiseDensity>
      <accelerometerRandomWalk>0.006</accelerometerRandomWalk>
      <accelerometerBiasCorrelationTime>300.0</accelerometerBiasCorrelationTime>
      <accelerometerTurnOnBiasSigma>0.196</accelerometerTurnOnBiasSigma>
    </plugin>

    <plugin name="gps_plugin" filename="libgazebo_gps_plugin.so">
        <robotNamespace></robotNamespace>
        <gpsNoise>true</gpsNoise>
    </plugin>
    <plugin name='magnetometer_plugin' filename='libgazebo_magnetometer_plugin.so'>
      <robotNamespace/>
      <pubRate>20</pubRate>
      <noiseDensity>0.0004</noiseDensity>
      <randomWalk>6.4e-06</randomWalk>
      <biasCorrelationTime>600</biasCorrelationTime>
      <magTopic>/mag</magTopic>
    </plugin>
    <plugin name='barometer_plugin' filename='libgazebo_barometer_plugin.so'>
      <robotNamespace/>
      <pubRate>10</pubRate>
      <baroTopic>/baro</baroTopic>
    </plugin> -->

    <!-- <plugin name='mavlink_interface' filename='librotors_gazebo_mavlink_interface.so'> -->
    <!-- <plugin name='mavlink_interface' filename='libgazebo_mavlink_interface.so'>
      <robotNamespace></robotNamespace>
      <imuSubTopic>/imu</imuSubTopic>
      <gpsSubTopic>/gps</gpsSubTopic>
      <magSubTopic>/mag</magSubTopic>
      <baroSubTopic>/baro</baroSubTopic>
      <mavlink_addr>INADDR_ANY</mavlink_addr>
      <mavlink_udp_port>14560</mavlink_udp_port>
      <serialEnabled>false</serialEnabled>
      <serialDevice>/dev/ttyACM0</serialDevice>
      <baudRate>921600</baudRate>
      <qgc_addr>INADDR_ANY</qgc_addr>
      <qgc_udp_port>14550</qgc_udp_port>
      <sdk_addr>INADDR_ANY</sdk_addr>
      <sdk_udp_port>14540</sdk_udp_port>
      <hil_mode>false</hil_mode>
      <hil_state_level>false</hil_state_level>
      <enable_lockstep>true</enable_lockstep>
      <use_tcp>true</use_tcp>
      <vehicle_is_tailsitter>true</vehicle_is_tailsitter>
      <motorSpeedCommandPubTopic>/gazebo/command/motor_speed</motorSpeedCommandPubTopic>
      <control_channels>
        <channel name="rotor_left">
          <input_index>0</input_index>
          <input_offset>0</input_offset>
          <input_scaling>800</input_scaling>
          <zero_position_disarmed>0</zero_position_disarmed>
          <zero_position_armed>0</zero_position_armed>
          <joint_control_type>velocity</joint_control_type>
          <joint_name>rotor_left_joint</joint_name>
        </channel>
        <channel name="rotor_right">
          <input_index>1</input_index>
          <input_offset>0</input_offset>
          <input_scaling>800</input_scaling>
          <zero_position_disarmed>0</zero_position_disarmed>
          <zero_position_armed>0</zero_position_armed>
          <joint_control_type>velocity</joint_control_type>
          <joint_name>rotor_right_joint</joint_name>
        </channel>
        <channel name="left_elevon">
          <input_index>4</input_index>
          <input_offset>0</input_offset>
          <input_scaling>1</input_scaling>
          <zero_position_disarmed>0</zero_position_disarmed>
          <zero_position_armed>0</zero_position_armed>
          <joint_control_type>position_kinematic</joint_control_type>
          <joint_name>left_elevon_joint</joint_name>
        </channel>
        <channel name="right_elevon">
          <input_index>5</input_index>
          <input_offset>0</input_offset>
          <input_scaling>1</input_scaling>
          <zero_position_disarmed>0</zero_position_disarmed>
          <zero_position_armed>0</zero_position_armed>
          <joint_control_type>position_kinematic</joint_control_type>
          <joint_name>right_elevon_joint</joint_name>
        </channel>
      </control_channels>
      <left_elevon_joint>
        left_elevon_joint
      </left_elevon_joint>
      <right_elevon_joint>
        right_elevon_joint
      </right_elevon_joint>
    </plugin> -->
    <static>0</static>
  </model>
</sdf>